{"uuid": "851715e6-5561-4edc-b912-bf5690ae330a", "children": ["05b44d78-8e30-40dc-8e02-1d6c90cde153"], "befores": [{"name": "_Class__pytest_setup_method", "status": "broken", "statusDetails": {"message": "urllib3.exceptions.MaxRetryError: HTTPConnectionPool(host='localhost', port=4723): Max retries exceeded with url: /wd/hub/session (Caused by NewConnectionError('<urllib3.connection.HTTPConnection object at 0x000001FADF485C88>: Failed to establish a new connection: [WinError 10061] 由于目标计算机积极拒绝，无法连接。'))\n", "trace": "  File \"D:\\Python\\Projectsvenv\\lib\\site-packages\\pluggy\\callers.py\", line 187, in _multicall\n    res = hook_impl.function(*args)\n  File \"D:\\Python\\Projectsvenv\\lib\\site-packages\\_pytest\\fixtures.py\", line 964, in pytest_fixture_setup\n    result = call_fixture_func(fixturefunc, request, kwargs)\n  File \"D:\\Python\\Projectsvenv\\lib\\site-packages\\_pytest\\fixtures.py\", line 788, in call_fixture_func\n    res = next(it)\n  File \"D:\\Python\\Projectsvenv\\lib\\site-packages\\_pytest\\python.py\", line 728, in xunit_setup_method_fixture\n    _call_with_optional_argument(func, method)\n  File \"D:\\Python\\Projectsvenv\\lib\\site-packages\\_pytest\\python.py\", line 636, in _call_with_optional_argument\n    func()\n  File \"C:\\Users\\HP\\Desktop\\Auto\\HooApp\\Scripts\\A_Register_test.py\", line 16, in setup_method\n    self.driver = webdriver.Remote('http://localhost:4723/wd/hub', setup_method.android_driver_caps)  # 串联\n  File \"D:\\Python\\Projectsvenv\\lib\\site-packages\\appium\\webdriver\\webdriver.py\", line 151, in __init__\n    proxy\n  File \"D:\\Python\\Projectsvenv\\lib\\site-packages\\selenium\\webdriver\\remote\\webdriver.py\", line 157, in __init__\n    self.start_session(capabilities, browser_profile)\n  File \"D:\\Python\\Projectsvenv\\lib\\site-packages\\appium\\webdriver\\webdriver.py\", line 227, in start_session\n    response = self.execute(RemoteCommand.NEW_SESSION, parameters)\n  File \"D:\\Python\\Projectsvenv\\lib\\site-packages\\selenium\\webdriver\\remote\\webdriver.py\", line 319, in execute\n    response = self.command_executor.execute(driver_command, params)\n  File \"D:\\Python\\Projectsvenv\\lib\\site-packages\\selenium\\webdriver\\remote\\remote_connection.py\", line 374, in execute\n    return self._request(command_info[0], url, body=data)\n  File \"D:\\Python\\Projectsvenv\\lib\\site-packages\\selenium\\webdriver\\remote\\remote_connection.py\", line 397, in _request\n    resp = self._conn.request(method, url, body=body, headers=headers)\n  File \"D:\\Python\\Projectsvenv\\lib\\site-packages\\urllib3\\request.py\", line 80, in request\n    method, url, fields=fields, headers=headers, **urlopen_kw\n  File \"D:\\Python\\Projectsvenv\\lib\\site-packages\\urllib3\\request.py\", line 171, in request_encode_body\n    return self.urlopen(method, url, **extra_kw)\n  File \"D:\\Python\\Projectsvenv\\lib\\site-packages\\urllib3\\poolmanager.py\", line 330, in urlopen\n    response = conn.urlopen(method, u.request_uri, **kw)\n  File \"D:\\Python\\Projectsvenv\\lib\\site-packages\\urllib3\\connectionpool.py\", line 760, in urlopen\n    **response_kw\n  File \"D:\\Python\\Projectsvenv\\lib\\site-packages\\urllib3\\connectionpool.py\", line 760, in urlopen\n    **response_kw\n  File \"D:\\Python\\Projectsvenv\\lib\\site-packages\\urllib3\\connectionpool.py\", line 760, in urlopen\n    **response_kw\n  File \"D:\\Python\\Projectsvenv\\lib\\site-packages\\urllib3\\connectionpool.py\", line 720, in urlopen\n    method, url, error=e, _pool=self, _stacktrace=sys.exc_info()[2]\n  File \"D:\\Python\\Projectsvenv\\lib\\site-packages\\urllib3\\util\\retry.py\", line 436, in increment\n    raise MaxRetryError(_pool, url, error or ResponseError(cause))\n"}, "start": 1597987992039, "stop": 1597988010103}], "start": 1597987992039, "stop": 1597988010590}